<?xml version="1.0" encoding="utf-8"?>
<!-- This URDF was automatically created by SolidWorks to URDF Exporter! Originally created by Stephen Brawner (brawner@gmail.com) 
     Commit Version: 1.6.0-1-g15f4949  Build Version: 1.6.7594.29634
     For more information, please see http://wiki.ros.org/sw_urdf_exporter -->
<robot
  name="Rotunbot">
  <link
    name="base_link">
    <inertial>
      <origin
        xyz="-0.0821 0.002235 0.002452"
        rpy="0 0 0" />
      <mass
        value="30.225" />
      <inertia
        ixx="1.1395"
        ixy="0.002423"
        ixz="0.002018"
        iyy="1.3014"
        iyz="0.003856"
        izz="1.8027" />
    </inertial>
    <visual>
      <origin
        xyz="0 0 0"
        rpy="-1.571 0 0" />
      <geometry>
        <mesh
          filename="../meshes/base_link.STL" />
      </geometry>
      <material
        name="">
        <color
          rgba="0.75294 0.75294 0.75294 1" />
      </material>
    </visual>
    <collision>
      <origin
        xyz="0 0 0"
        rpy="0 0 0" />
      <geometry>
        <cylinder length="0.005" radius="0.02"/>
      </geometry>
    </collision>
  </link>
  <link
    name="link1">
    <inertial>
      <origin
        xyz="0.000176 -0.000666 -0.001"
        rpy="0 0 0" />
      <mass
        value="27.834" />
      <inertia
        ixx="2.3603"
        ixy="0.000592"
        ixz="4.36E-05"
        iyy="1.8803"
        iyz="0.000106"
        izz="2.3606" />
    </inertial>
    <visual>
      <origin
        xyz="0 0 0"
        rpy="-1.571 0 0" />
      <geometry>
        <mesh
          filename="../meshes/link1.STL" />
      </geometry>
      <material
        name="">
        <color
          rgba="0.75294 0.75294 0.75294 1" />
      </material>
    </visual>
    <collision>
      <origin
        xyz="0 0 0"
        rpy="0 0 0" />
      <geometry>
        <sphere radius="0.4"/>
      </geometry>
    </collision>
  </link>
  <joint
    name="joint1"
    type="continuous">
    <origin
      xyz="0 0 0"
      rpy="0 0.00011905 0" />
    <parent
      link="base_link" />
    <child
      link="link1" />
    <axis
      xyz="0 1 0" />
    <limit
      lower="-0.5236"
      upper="0.5236"
      effort="50"
      velocity="10" />
  </joint>
  <link
    name="link2">
    <inertial>
      <origin
        xyz="0.004257 0.000289 -0.270243"
        rpy="0 0 0" />
      <mass
        value="82.8" />
      <inertia
        ixx="6.9568"
        ixy="0.004242"
        ixz="-0.005461"
        iyy="7.9816"
        iyz="-0.000712"
        izz="1.7644" />
    </inertial>
    <visual>
      <origin
        xyz="0 0 0"
        rpy="-1.571 0 0" />
      <geometry>
        <mesh
          filename="../meshes/link2.STL" />
      </geometry>
      <material
        name="">
        <color
          rgba="0.75294 0.75294 0.75294 1" />
      </material>
    </visual>
    <collision>
      <origin
        xyz="0 0 0"
        rpy="0 0 0" />
      <geometry>
        <cylinder length="0.005" radius="0.02"/>
      </geometry>
    </collision>
  </link>
  <joint
    name="joint2"
    type="revolute">
    <origin
      xyz="0 0 0"
      rpy="0 0 0" />
    <parent
      link="base_link" />
    <child
      link="link2" />
    <axis
      xyz="-1 0 0" />
    <limit
      lower="-0.5236"
      upper="0.5236"
      effort="500"
      velocity="50" />
  </joint>
</robot>